<mujoco model="door_knob">
	<compiler angle="radian"/>
	<option timestep="0.001"/>
	<asset>
		<mesh file="./1558288438/body_1.stl" name="door_knob_1" scale="0.001 0.001 0.001"/>
		<mesh file="./1558288438/body_2.stl" name="door_knob_2" scale="0.001 0.001 0.001"/>
		<texture builtin="flat" height="32" name="wall_geom" type="2d" width="32"/>
		<texture builtin="flat" height="32" name="frame_geom" type="2d" width="32"/>
		<texture builtin="flat" height="32" name="door_geom" type="2d" width="32"/>
		<texture builtin="flat" height="32" name="knob_geom" type="2d" width="32"/>
		<texture builtin="gradient" height="256" rgb1=".9 .9 1." rgb2=".2 .3 .4" type="skybox" width="256"/>
    	<texture builtin="checker" height="512" name="texplane" rgb1=".2 .3 .4" rgb2=".1 0.15 0.2" type="2d" width="512"/>
		<material name="Paint" shininess="0.35" specular="0.22" texture="wall_geom"/>
		<material name="Wood" shininess="0.05" specular="0.01" texture="frame_geom"/>
		<material name="Carpet" shininess="0.01" specular="0.03" texture="door_geom"/>
		<material name="Metal" shininess="0.86" specular="0.96" texture="knob_geom"/>
		<material name="Floor" texture="texplane"/>
	</asset>
	<contact>
		<pair geom1="knob_latch" geom2="door_frame_0" solref="0.01 1"/>
		<pair geom1="knob_latch" geom2="door_frame_1" solref="0.01 1"/>
		<pair geom1="knob_latch" geom2="door_frame_2" solref="0.01 1"/>
		<pair geom1="knob_latch" geom2="door_frame_3" solref="0.01 1"/>
	</contact>
	<default>
		<joint armature="1" damping="1" limited="true"/>
		<default class="wall">
			<geom rgba="0.51 0.52 0.35 1.0" type="mesh"/>
		</default>
		<default class="frame">
			<geom rgba="0.79 0.73 0.78 1.0" type="mesh"/>
		</default>
		<default class="door">
			<geom rgba="0.02 0.3 0.43 1.0" type="mesh"/>
		</default>
		<default class="door_knob">
			<geom condim="4" rgba="0.3 0.08 0.4 1.0" type="mesh"/>
		</default>
		<default class="robot">
			<joint damping="0.1"/>
		</default>
	</default>
	<worldbody>
		<geom material="Floor" name="floor" pos="0 0 -0.05" size="15.0 15.0 0.05" type="plane"/>

		<body childclass="wall" name="wall_link" pos="0.0 0.0 0.0">
			<inertial mass="100" pos="0 0 0" diaginertia="0.0001 0.0001 0.0001"/>
			<geom material="Wood" name="wall_0" pos="-0.15 -1.57 1.145" size="0.15 1.0 1.145" type="box" euler="0 0 0" group="1"/>
			<geom material="Wood" name="wall_1" pos="-0.15 1.6 1.145" size="0.15 1.0 1.145" type="box" euler="0 0 0" group="1"/>
			<geom material="Wood" name="wall_2" pos="-0.15 0 2.79" size="0.15 2.6 0.5" type="box" euler="0 0 0" group="1"/>
			<body childclass="frame" name="frame_link" pos="0 -0.35 1">
				<inertial mass="500" pos="0 0 0" diaginertia="0.0001 0.0001 0.0001"/>
				<geom material="Wood" name="door_frame_0" pos="0 -0.21000000000000002 0.14500000000000002" size="0.0135 0.05 1.145" type="box" euler="0 0 0" group="1"/>
				<geom material="Wood" name="door_frame_1" pos="0 0.91 0.14500000000000002" size="0.0135 0.05 1.145" type="box" euler="0 0 0" group="1"/>
				<geom material="Wood" name="door_frame_2" pos="0 0.35 1.24" size="0.0135 0.6 0.05" type="box" euler="0 0 0" group="1"/>
				<geom material="Wood" name="door_frame_3" pos="-0.0465 -0.21000000000000002 0.14500000000000002" size="0.0135 0.05 1.145" type="box" euler="0 0 0" group="1"/>
				<geom material="Wood" name="door_frame_4" pos="-0.0465 0.91 0.14500000000000002" size="0.0135 0.05 1.145" type="box" euler="0 0 0" group="1"/>
				<geom material="Wood" name="door_frame_5" pos="-0.0465 0.35 1.24" size="0.0135 0.6 0.05" type="box" euler="0 0 0" group="1"/>
				<body childclass="door" name="door_link" pos="0 0 0">
					<joint armature="0.0001" axis="0 0 1" damping="1.9" frictionloss="0" limited="true" name="hinge0" pos="0 0.85 0" range="-0.0 1.57" stiffness="0." type="hinge"/>
					<geom material="Wood" name="door0" pos="0 0.35 0.09499999999999997" size="0.0135 0.5 1.08405" type="box" euler="0 0 0" group="1"/>
					<inertial mass="0.80424" pos="0 0.35 0.11699999999999999" diaginertia="0.4015004671 0.3346907064 0.0670586035"/>
					<body childclass="door_knob" name="knob_link" pos="0 0 0">
						<inertial mass="1" pos="0 0 0" diaginertia="0.001 0.001 0.001"/>
						<joint armature="0" axis="0 1 0" damping="30000" frictionloss="0" limited="true" name="target0" range="-0.2 0.3" stiffness="0" type="slide"/>
						<joint armature="0" axis="0 0 1" damping="30000" frictionloss="0" limited="true" name="target1" range="-0.5 0.5" stiffness="0" type="slide"/>
						<joint armature="0.0001" axis="1 0 0" damping="1.82" frictionloss="0" limited="true" name="hinge1" pos="0 0 0" range="-1.57 1.57" stiffness="0.1" type="hinge"/>
						<body childclass="door_knob" name="roundknob_link" pos="0.0135 0 0">
							<geom friction="0.92 0.004 0.004" material="Paint" mesh="door_knob_1" name="door_knob_1" euler="-1.57 1.57 0" group="1"/>
							<geom friction="0.92 0.004 0.004" material="Paint" mesh="door_knob_2" name="door_knob_2" euler="-1.57 1.57 0" group="1"/>
							<geom material="Paint" name="knob_latch" pos="-0.03675 0 0" size="0.0075 0.16333333333333332 0.05" type="box" euler="0 0 0" group="1"/>
							<inertial mass="1" pos="-0.06645 0 0" diaginertia="0.003009259259259259 0.00022708333333333337 0.0028196759259259256"/>
						</body>
					</body>
				</body>
			</body>
		</body>

		<light diffuse=".9 .9 .9" dir="0 0 -1" directional="false" pos="1 0 4.0" specular="0.3 0.3 0.3" castshadow="false"/>
    	<light diffuse=".9 .9 .9" dir="0 0 -1" directional="false" pos="1. -0.5 4.0" specular="0.3 0.3 0.3" castshadow="false"/>
    	<light diffuse=".9 .9 .9" dir="0 0 -1" directional="false" pos="1. 0.5 4.0" specular="0.3 0.3 0.3" castshadow="false"/>
		<light diffuse=".9 .9 .9" dir="-1 0 0" directional="false" pos="3. 0. 1.0" specular="0.3 0.3 0.3" castshadow="false"/>
		<camera fovy="60" mode="fixed" name="sideview" pos="1.0 -2.5 1.2" euler="1.57079633,  1.22173048, -0."/>
		<!-- side view --> 
		<camera fovy="60" mode="fixed" name="frontview" pos="2.0 -0.5 1.5" euler="0.0 1.27 1.57"/>
		<!-- bird view -->
		<camera fovy="60" mode="fixed" name="birdview" pos="0.5 0.0 1.99" euler="0 0 0"/>
    	<!-- agent view -->
    	<camera mode="fixed" name="agentview" pos="1.0 0.4 1.75" quat="0.653 0.271 0.271 0.653"/>
	</worldbody>
</mujoco>
